Workbook

Sheet Guide
B1: Performance Qualification & Recognition Matrix — User Guide
B2: Draft v0.1 · 2026-09-29 · Sample data included for illustration (fictional employees) — clear log input cells before live use.
B4: Workbook Map
B5: Rewards_Program | C5: Concept of the PRIDE recognition & accountability program (purpose, categories, cross-department recognition, promotional activities, governance).
B6: Dashboard | C6: KPI tiles, department summary, COQ by category, charts. Read-only.
B7: Merit_Scorecard | C7: Per-employee net merit, standing and reward eligibility for the review period (set Period Start/End in yellow cells).
B8: Qualification_Log | C8: Process Trainer log: certifications, assessments, quality incidents with Cost of Quality (COQ), severity and decertification.
B9: Recognition_Log | C9: Merit side: nominations, Cross-Department Recognition, Division Lead approval, awards.
B10: Corrective_Action_Log | C10: Accountability side: progressive corrective actions with due-process dates and demerit points.
B11: Employee_Master | C11: Employee register. Employee ID is the key linking every log (like a database primary key).
B12: Reference_Data | C12: Master lists for all dropdowns, point values, severity definitions and scoring thresholds (yellow).
B14: How to Use
B15: Step 1 | C15: Add employees to Employee_Master (unique Employee ID, Department, Division Lead, Process Trainer).
B16: Step 2 | C16: Process Trainer logs each certification in Qualification_Log (Event Type = Initial Certification / Recertification / Reinstatement, Certification Level, Score, Certification Date). Expiry and Status calculate automatically.
B17: Step 3 | C17: For each quality event, log Event Type = Quality Incident with COQ Category, description, COQ Amount (PHP) and Severity. The Recommended Action appears automatically.
B18: Step 4 | C18: Record the formal action in Corrective_Action_Log, referencing the Log ID. Enter Decision Date only after due process — demerits count from that point.
B19: Step 5 | C19: To decertify, log a row with Event Type = Decertification, Decertification = Yes, Date and Reason. The original certification row changes to 'Decertified'. Reinstate by logging a new certification row.
B20: Step 6 | C20: Log recognitions in Recognition_Log. Cross-Department is flagged automatically; Division Lead must approve before points credit.
B21: Step 7 | C21: Review Merit_Scorecard and Dashboard monthly; calibrate thresholds on Reference_Data quarterly.
B23: Conventions
B24: Navy header | C24: Input column — type or select from dropdown.
B25: Grey header / shaded cell | C25: Formula — do not overwrite.
B26: Blue text, yellow fill | C26: Editable parameter (Reference_Data, Scorecard period).
B27: IDs | C27: Enter sequential IDs manually (QL-0001, RC-0001, CA-0001). Do not reuse or renumber — other logs reference them.
B28: Capacity | C28: Logs are pre-formatted for 300 rows (rows 5–304); Employee_Master and Scorecard for 100 employees. To extend, copy the last row's formulas down and widen formula ranges.
B29: Status values | C29: Active · Expired (past expiry — recertify) · Decertified · Superseded (replaced by a newer certification for the same process) · Decertification Record.
B31: Cautions
B32: Multi-user | C32: A desktop Excel file is not suited to simultaneous editing. Host on SharePoint / OneDrive (Excel Online co-authoring) or migrate the tables to a database / Salesforce object when volume grows.
B33: HR / Legal | C33: Corrective action ladder, point values and due-process steps are proposals. Validate with HR and applicable labor regulations before use; this workbook is a tracking tool, not the official disciplinary record.
B34: Data privacy | C34: Contains personnel performance and disciplinary data. Restrict access (protect sheets / limit sharing) to Process Trainers, Leads, Division Leads and HR.
B35: Scoring | C35: Point values and thresholds are uncalibrated starting points. Review after the first pilot quarter.

Sheet Rewards_Program
B1: PRIDE Program — Performance, Recognition, Integrity, Dedication & Excellence
B2: Concept Draft v0.1 · Employee Recognition and Performance Accountability Program · Prepared 2026-09-29 · For review by Division Leads and HR
B3: Program name is a proposed working title. All point values and thresholds are proposals for calibration and are maintained on the Reference_Data tab.
B5: 1. Purpose
B6: Establish a fair, transparent and data-driven framework that recognizes employees who consistently deliver quality work, support other teams and improve processes — and that applies consistent, documented and proportionate corrective action when performance or quality standards are not met.
B7: The program links three existing disciplines into one record: (a) process qualification and certification managed by Process Trainers, (b) Cost of Quality (COQ) tracking, and (c) recognition and corrective action.
B9: 2. Objectives
B10: • Increase First Pass Yield and reduce Cost of Poor Quality (internal and external failure costs).
B11: • Ensure every employee performing a process holds a current, valid certification for that process.
B12: • Recognize high performance, mentorship, innovation and cross-department collaboration in a timely and visible manner.
B13: • Apply corrective action consistently across departments, following due process.
B14: • Give leadership a single, auditable view of competency, quality cost and employee standing.
... B30: Point values below are pulled live from Reference_Data; changing them there updates this table and all scoring.
B31: Recognition Type | C31: Criteria | F31: Merit Points
B32: =Reference_Data!O5 -> Spot Award | C32: =Reference_Data!Q5 -> Immediate recognition of an above-standard contribution. | F32: =Reference_Data!P5 -> 10
B33: =Reference_Data!O6 -> Cross-Department Recognition | C33: =Reference_Data!Q6 -> Significant assistance that helped another department achieve a goal. Division Lead approval required. | F33: =Reference_Data!P6 -> 15
B34: =Reference_Data!O7 -> Mentorship Award | C34: =Reference_Data!Q7 -> Coached peers to a higher certification level. | F34: =Reference_Data!P7 -> 15
B35: =Reference_Data!O8 -> Quality Excellence Award | C35: =Reference_Data!Q8 -> Sustained zero-defect / top First Pass Yield performance. | F35: =Reference_Data!P8 -> 20
B36: =Reference_Data!O9 -> Zero-Defect Milestone | C36: =Reference_Data!Q9 -> Consecutive-output milestone with zero QA findings. | F36: =Reference_Data!P9 -> 20
B37: =Reference_Data!O10 -> Innovation / Process Improvement | C37: =Reference_Data!Q10 -> Improvement adopted that measurably reduces COQ or cycle time. | F37: =Reference_Data!P10 -> 25
B38: =Reference_Data!O11 -> Employee of the Quarter | C38: =Reference_Data!Q11 -> Top overall contributor for the quarter (committee selection). | F38: =Reference_Data!P11 -> 40
B40: 6. Cross-Department Recognition
B41: Rewards may be given across departments when an employee provides significant assistance, support or contribution that helps another team or department achieve its goals or successfully complete an activity or project. Such rewards are subject to review and approval by the respective Division Lead.
B42: Process:
B43: 1. Nomination — any Team Lead or employee of the benefiting department submits a nomination describing the assistance, the goal or project supported, and the measurable outcome.
B44: 2. Logging — the nomination is entered in Recognition_Log with Recognition Type = 'Cross-Department Recognition' and the Beneficiary Department. The Cross-Department flag sets automatically when the Beneficiary Department differs from the employee's Home Department.
B45: 3. Review — the Division Lead of the benefiting department validates the contribution and impact. (Missing approver names are highlighted in red.)
B46: 4. Approval — the Division Lead sets Approval Status and Approval Date. Merit points credit only when Approved.
B47: 5. Award & Communication — the award is issued, and the recognition is shared with both departments.
B48: Qualifying contributions (examples): covering critical workload to meet a builder or utility deadline; sharing technical expertise that resolves another team's blocker; co-developing a tool, template or checklist adopted by another department; supporting a launch, audit or backlog-clearance initiative.
B50: 7. Performance Accountability Framework (Demerit)
B51: Quality events are logged in Qualification_Log with COQ category and amount. Severity determines the recommended corrective action, which is then formally recorded in Corrective_Action_Log.
B52: Severity | C52: Definition | F52: Recommended Action
B53: =Reference_Data!H5 -> Minor | C53: =Reference_Data!I5 -> Defect caught internally; no customer, AHJ or utility impact; COQ below ₱5,000. | F53: =Reference_Data!J5 -> Coaching Session
B54: =Reference_Data!H6 -> Major | C54: =Reference_Data!I6 -> Defect reached AHJ / utility / customer OR required formal rework; schedule impact. | F54: =Reference_Data!J6 -> Written Warning + Retraining
B55: =Reference_Data!H7 -> Critical | C55: =Reference_Data!I7 -> Safety, code or compliance risk, field rework, or repeat Major within 90 days. | F55: =Reference_Data!J7 -> Decertification Review / Final Written Warning
B57: Progressive corrective action ladder (demerit points from Reference_Data):
B58: Corrective Action | C58: Description | F58: Demerit Points
B59: =Reference_Data!S5 -> Coaching Session | C59: =Reference_Data!U5 -> Documented one-on-one coaching; non-disciplinary. | F59: =Reference_Data!T5 -> 0
B60: =Reference_Data!S6 -> Verbal Warning | C60: =Reference_Data!U6 -> Documented verbal warning. | F60: =Reference_Data!T6 -> 5
...

Sheet Dashboard
A1: Performance & Recognition Dashboard
A2: All figures auto-calculate from the logs. Period is set on Merit_Scorecard.
A3: ="Review period: "&TEXT(Merit_Scorecard!B3,"yyyy-mm-dd")&" to "&TEXT(Merit_Scorecard!B4,"yyyy-mm-dd") -> Review period: 2026-01-01 to 2026-12-31
A5: Active Employees | C5: Active Certifications | E5: Decertifications | G5: Cost of Quality (PHP) | I5: Merit Points Awarded | K5: Demerit Points Issued | M5: Cross-Dept Recognitions | O5: Open Corrective Actions
A6: =COUNTIFS(Employee_Master!$H$5:$H$104,"Active") -> 10 | C6: =SUM(Merit_Scorecard!$D$7:$D$106) -> 9 | E6: =SUM(Merit_Scorecard!$E$7:$E$106) -> 1 | G6: =SUM(Merit_Scorecard!$H$7:$H$106) -> 82000 | I6: =SUM(Merit_Scorecard!$J$7:$J$106) -> 120 | K6: =SUM(Merit_Scorecard!$K$7:$K$106) -> 50 | M6: =COUNTIFS(Recognition_Log!$H$5:$H$304,"Yes",Recognition_Log!$N$5:$N$304,"Approved",Recognition_Log!$O$5:$O$304,">="&Merit_Scorecard!$B$3,Recognition_Log!$O$5:$O$304,"<="&Merit_Scorecard!$B$4) -> 3 | O6: =COUNTIFS(Corrective_Action_Log!$S$5:$S$304,"Open") -> 1
A8: Summary by Department
A9: Department | B9: Headcount | C9: Active Certs | D9: Decerts | E9: Quality Incidents | F9: Critical | G9: COQ (PHP) | H9: Recognitions | I9: Cross-Dept Given | J9: Cross-Dept Received | K9: Corrective Actions | L9: Merit Points | M9: Demerit Points | N9: Avg Net Merit
A10: =IF(Reference_Data!A5="","",Reference_Data!A5) -> Design | B10: =IF($A10="","",COUNTIFS(Employee_Master!$C$5:$C$104,$A10,Employee_Master!$H$5:$H$104,"Active")) -> 3 | C10: =IF($A10="","",SUMIFS(Merit_Scorecard!$D$7:$D$106,Merit_Scorecard!$C$7:$C$106,$A10)) -> 4 | D10: =IF($A10="","",SUMIFS(Merit_Scorecard!$E$7:$E$106,Merit_Scorecard!$C$7:$C$106,$A10)) -> 1 | E10: =IF($A10="","",SUMIFS(Merit_Scorecard!$F$7:$F$106,Merit_Scorecard!$C$7:$C$106,$A10)) -> 3 | F10: =IF($A10="","",SUMIFS(Merit_Scorecard!$G$7:$G$106,Merit_Scorecard!$C$7:$C$106,$A10)) -> 1 | G10: =IF($A10="","",SUMIFS(Merit_Scorecard!$H$7:$H$106,Merit_Scorecard!$C$7:$C$106,$A10)) -> 60500 | H10: =IF($A10="","",SUMIFS(Merit_Scorecard!$I$7:$I$106,Merit_Scorecard!$C$7:$C$106,$A10)) -> 3 | I10: =IF($A10="","",COUNTIFS(Recognition_Log!$E$5:$E$304,$A10,Recognition_Log!$H$5:$H$304,"Yes",Recognition_Log!$N$5:$N$304,"Approved",Recognition_Log!$O$5:$O$304,">="&Merit_Scorecard!$B$3,Recognition_Log!$O$5:$O$304,"<="&Merit_Scorecard!$B$4)) -> 1 | J10: =IF($A10="","",COUNTIFS(Recognition_Log!$G$5:$G$304,$A10,Recognition_Log!$H$5:$H$304,"Yes",Recognition_Log!$N$5:$N$304,"Approved",Recognition_Log!$O$5:$O$304,">="&Merit_Scorecard!$B$3,Recognition_Log!$O$5:$O$304,"<="&Merit_Scorecard!$B$4)) -> 1 | K10: =IF($A10="","",COUNTIFS(Corrective_Action_Log!$E$5:$E$304,$A10,Corrective_Action_Log!$N$5:$N$304,">="&Merit_Scorecard!$B$3,Corrective_Action_Log!$N$5:$N$304,"<="&Merit_Scorecard!$B$4)) -> 3 | L10: =IF($A10="","",SUMIFS(Merit_Scorecard!$J$7:$J$106,Merit_Scorecard!$C$7:$C$106,$A10)) -> 60 | M10: =IF($A10="","",SUMIFS(Merit_Scorecard!$K$7:$K$106,Merit_Scorecard!$C$7:$C$106,$A10)) -> 45 | N10: =IF($A10="","",IFERROR(AVERAGEIF(Merit_Scorecard!$C$7:$C$106,$A10,Merit_Scorecard!$L$7:$L$106),0)) -> 5
A11: =IF(Reference_Data!A6="","",Reference_Data!A6) -> Permitting | B11: =IF($A11="","",COUNTIFS(Employee_Master!$C$5:$C$104,$A11,Employee_Master!$H$5:$H$104,"Active")) -> 2 | C11: =IF($A11="","",SUMIFS(Merit_Scorecard!$D$7:$D$106,Merit_Scorecard!$C$7:$C$106,$A11)) -> 1 | D11: =IF($A11="","",SUMIFS(Merit_Scorecard!$E$7:$E$106,Merit_Scorecard!$C$7:$C$106,$A11)) -> 0 | E11: =IF($A11="","",SUMIFS(Merit_Scorecard!$F$7:$F$106,Merit_Scorecard!$C$7:$C$106,$A11)) -> 1 | F11: =IF($A11="","",SUMIFS(Merit_Scorecard!$G$7:$G$106,Merit_Scorecard!$C$7:$C$106,$A11)) -> 0 | G11: =IF($A11="","",SUMIFS(Merit_Scorecard!$H$7:$H$106,Merit_Scorecard!$C$7:$C$106,$A11)) -> 9500 | H11: =IF($A11="","",SUMIFS(Merit_Scorecard!$I$7:$I$106,Merit_Scorecard!$C$7:$C$106,$A11)) -> 1 | I11: =IF($A11="","",COUNTIFS(Recognition_Log!$E$5:$E$304,$A11,Recognition_Log!$H$5:$H$304,"Yes",Recognition_Log!$N$5:$N$304,"Approved",Recognition_Log!$O$5:$O$304,">="&Merit_Scorecard!$B$3,Recognition_Log!$O$5:$O$304,"<="&Merit_Scorecard!$B$4)) -> 0 | J11: =IF($A11="","",COUNTIFS(Recognition_Log!$G$5:$G$304,$A11,Recognition_Log!$H$5:$H$304,"Yes",Recognition_Log!$N$5:$N$304,"Approved",Recognition_Log!$O$5:$O$304,">="&Merit_Scorecard!$B$3,Recognition_Log!$O$5:$O$304,"<="&Merit_Scorecard!$B$4)) -> 1 | K11: =IF($A11="","",COUNTIFS(Corrective_Action_Log!$E$5:$E$304,$A11,Corrective_Action_Log!$N$5:$N$304,">="&Merit_Scorecard!$B$3,Corrective_Action_Log!$N$5:$N$304,"<="&Merit_Scorecard!$B$4)) -> 0 | L11: =IF($A11="","",SUMIFS(Merit_Scorecard!$J$7:$J$106,Merit_Scorecard!$C$7:$C$106,$A11)) -> 10 | M11: =IF($A11="","",SUMIFS(Merit_Scorecard!$K$7:$K$106,Merit_Scorecard!$C$7:$C$106,$A11)) -> 0 | N11: =IF($A11="","",IFERROR(AVERAGEIF(Merit_Scorecard!$C$7:$C$106,$A11,Merit_Scorecard!$L$7:$L$106),0)) -> 5
A12: =IF(Reference_Data!A7="","",Reference_Data!A7) -> Interconnection | B12: =IF($A12="","",COUNTIFS(Employee_Master!$C$5:$C$104,$A12,Employee_Master!$H$5:$H$104,"Active")) -> 2 | C12: =IF($A12="","",SUMIFS(Merit_Scorecard!$D$7:$D$106,Merit_Scorecard!$C$7:$C$106,$A12)) -> 2 | D12: =IF($A12="","",SUMIFS(Merit_Scorecard!$E$7:$E$106,Merit_Scorecard!$C$7:$C$106,$A12)) -> 0 | E12: =IF($A12="","",SUMIFS(Merit_Scorecard!$F$7:$F$106,Merit_Scorecard!$C$7:$C$106,$A12)) -> 1 | F12: =IF($A12="","",SUMIFS(Merit_Scorecard!$G$7:$G$106,Merit_Scorecard!$C$7:$C$106,$A12)) -> 0 | G12: =IF($A12="","",SUMIFS(Merit_Scorecard!$H$7:$H$106,Merit_Scorecard!$C$7:$C$106,$A12)) -> 2500 | H12: =IF($A12="","",SUMIFS(Merit_Scorecard!$I$7:$I$106,Merit_Scorecard!$C$7:$C$106,$A12)) -> 1 | I12: =IF($A12="","",COUNTIFS(Recognition_Log!$E$5:$E$304,$A12,Recognition_Log!$H$5:$H$304,"Yes",Recognition_Log!$N$5:$N$304,"Approved",Recognition_Log!$O$5:$O$304,">="&Merit_Scorecard!$B$3,Recognition_Log!$O$5:$O$304,"<="&Merit_Scorecard!$B$4)) -> 1 | J12: =IF($A12="","",COUNTIFS(Recognition_Log!$G$5:$G$304,$A12,Recognition_Log!$H$5:$H$304,"Yes",Recognition_Log!$N$5:$N$304,"Approved",Recognition_Log!$O$5:$O$304,">="&Merit_Scorecard!$B$3,Recognition_Log!$O$5:$O$304,"<="&Merit_Scorecard!$B$4)) -> 0 | K12: =IF($A12="","",COUNTIFS(Corrective_Action_Log!$E$5:$E$304,$A12,Corrective_Action_Log!$N$5:$N$304,">="&Merit_Scorecard!$B$3,Corrective_Action_Log!$N$5:$N$304,"<="&Merit_Scorecard!$B$4)) -> 1 | L12: =IF($A12="","",SUMIFS(Merit_Scorecard!$J$7:$J$106,Merit_Scorecard!$C$7:$C$106,$A12)) -> 15 | M12: =IF($A12="","",SUMIFS(Merit_Scorecard!$K$7:$K$106,Merit_Scorecard!$C$7:$C$106,$A12)) -> 0 | N12: =IF($A12="","",IFERROR(AVERAGEIF(Merit_Scorecard!$C$7:$C$106,$A12,Merit_Scorecard!$L$7:$L$106),0)) -> 7.5
A13: =IF(Reference_Data!A8="","",Reference_Data!A8) -> Quality Assurance | B13: =IF($A13="","",COUNTIFS(Employee_Master!$C$5:$C$104,$A13,Employee_Master!$H$5:$H$104,"Active")) -> 2 | C13: =IF($A13="","",SUMIFS(Merit_Scorecard!$D$7:$D$106,Merit_Scorecard!$C$7:$C$106,$A13)) -> 2 | D13: =IF($A13="","",SUMIFS(Merit_Scorecard!$E$7:$E$106,Merit_Scorecard!$C$7:$C$106,$A13)) -> 0 | E13: =IF($A13="","",SUMIFS(Merit_Scorecard!$F$7:$F$106,Merit_Scorecard!$C$7:$C$106,$A13)) -> 0 | F13: =IF($A13="","",SUMIFS(Merit_Scorecard!$G$7:$G$106,Merit_Scorecard!$C$7:$C$106,$A13)) -> 0 | G13: =IF($A13="","",SUMIFS(Merit_Scorecard!$H$7:$H$106,Merit_Scorecard!$C$7:$C$106,$A13)) -> 9500 | H13: =IF($A13="","",SUMIFS(Merit_Scorecard!$I$7:$I$106,Merit_Scorecard!$C$7:$C$106,$A13)) -> 2 | I13: =IF($A13="","",COUNTIFS(Recognition_Log!$E$5:$E$304,$A13,Recognition_Log!$H$5:$H$304,"Yes",Recognition_Log!$N$5:$N$304,"Approved",Recognition_Log!$O$5:$O$304,">="&Merit_Scorecard!$B$3,Recognition_Log!$O$5:$O$304,"<="&Merit_Scorecard!$B$4)) -> 1 | J13: =IF($A13="","",COUNTIFS(Recognition_Log!$G$5:$G$304,$A13,Recognition_Log!$H$5:$H$304,"Yes",Recognition_Log!$N$5:$N$304,"Approved",Recognition_Log!$O$5:$O$304,">="&Merit_Scorecard!$B$3,Recognition_Log!$O$5:$O$304,"<="&Merit_Scorecard!$B$4)) -> 1 | K13: =IF($A13="","",COUNTIFS(Corrective_Action_Log!$E$5:$E$304,$A13,Corrective_Action_Log!$N$5:$N$304,">="&Merit_Scorecard!$B$3,Corrective_Action_Log!$N$5:$N$304,"<="&Merit_Scorecard!$B$4)) -> 0 | L13: =IF($A13="","",SUMIFS(Merit_Scorecard!$J$7:$J$106,Merit_Scorecard!$C$7:$C$106,$A13)) -> 35 | M13: =IF($A13="","",SUMIFS(Merit_Scorecard!$K$7:$K$106,Merit_Scorecard!$C$7:$C$106,$A13)) -> 0 | N13: =IF($A13="","",IFERROR(AVERAGEIF(Merit_Scorecard!$C$7:$C$106,$A13,Merit_Scorecard!$L$7:$L$106),0)) -> 17.5
A14: =IF(Reference_Data!A9="","",Reference_Data!A9) -> Project Management | B14: =IF($A14="","",COUNTIFS(Employee_Master!$C$5:$C$104,$A14,Employee_Master!$H$5:$H$104,"Active")) -> 1 | C14: =IF($A14="","",SUMIFS(Merit_Scorecard!$D$7:$D$106,Merit_Scorecard!$C$7:$C$106,$A14)) -> 0 | D14: =IF($A14="","",SUMIFS(Merit_Scorecard!$E$7:$E$106,Merit_Scorecard!$C$7:$C$106,$A14)) -> 0 | E14: =IF($A14="","",SUMIFS(Merit_Scorecard!$F$7:$F$106,Merit_Scorecard!$C$7:$C$106,$A14)) -> 0 | F14: =IF($A14="","",SUMIFS(Merit_Scorecard!$G$7:$G$106,Merit_Scorecard!$C$7:$C$106,$A14)) -> 0 | G14: =IF($A14="","",SUMIFS(Merit_Scorecard!$H$7:$H$106,Merit_Scorecard!$C$7:$C$106,$A14)) -> 0 | H14: =IF($A14="","",SUMIFS(Merit_Scorecard!$I$7:$I$106,Merit_Scorecard!$C$7:$C$106,$A14)) -> 0 | I14: =IF($A14="","",COUNTIFS(Recognition_Log!$E$5:$E$304,$A14,Recognition_Log!$H$5:$H$304,"Yes",Recognition_Log!$N$5:$N$304,"Approved",Recognition_Log!$O$5:$O$304,">="&Merit_Scorecard!$B$3,Recognition_Log!$O$5:$O$304,"<="&Merit_Scorecard!$B$4)) -> 0 | J14: =IF($A14="","",COUNTIFS(Recognition_Log!$G$5:$G$304,$A14,Recognition_Log!$H$5:$H$304,"Yes",Recognition_Log!$N$5:$N$304,"Approved",Recognition_Log!$O$5:$O$304,">="&Merit_Scorecard!$B$3,Recognition_Log!$O$5:$O$304,"<="&Merit_Scorecard!$B$4)) -> 0 | K14: =IF($A14="","",COUNTIFS(Corrective_Action_Log!$E$5:$E$304,$A14,Corrective_Action_Log!$N$5:$N$304,">="&Merit_Scorecard!$B$3,Corrective_Action_Log!$N$5:$N$304,"<="&Merit_Scorecard!$B$4)) -> 1 | L14: =IF($A14="","",SUMIFS(Merit_Scorecard!$J$7:$J$106,Merit_Scorecard!$C$7:$C$106,$A14)) -> 0 | M14: =IF($A14="","",SUMIFS(Merit_Scorecard!$K$7:$K$106,Merit_Scorecard!$C$7:$C$106,$A14)) -> 5 | N14: =IF($A14="","",IFERROR(AVERAGEIF(Merit_Scorecard!$C$7:$C$106,$A14,Merit_Scorecard!$L$7:$L$106),0)) -> -5
A15: =IF(Reference_Data!A10="","",Reference_Data!A10) -> Customer Care | B15: =IF($A15="","",COUNTIFS(Employee_Master!$C$5:$C$104,$A15,Employee_Master!$H$5:$H$104,"Active")) -> 0 | C15: =IF($A15="","",SUMIFS(Merit_Scorecard!$D$7:$D$106,Merit_Scorecard!$C$7:$C$106,$A15)) -> 0 | D15: =IF($A15="","",SUMIFS(Merit_Scorecard!$E$7:$E$106,Merit_Scorecard!$C$7:$C$106,$A15)) -> 0 | E15: =IF($A15="","",SUMIFS(Merit_Scorecard!$F$7:$F$106,Merit_Scorecard!$C$7:$C$106,$A15)) -> 0 | F15: =IF($A15="","",SUMIFS(Merit_Scorecard!$G$7:$G$106,Merit_Scorecard!$C$7:$C$106,$A15)) -> 0 | G15: =IF($A15="","",SUMIFS(Merit_Scorecard!$H$7:$H$106,Merit_Scorecard!$C$7:$C$106,$A15)) -> 0 | H15: =IF($A15="","",SUMIFS(Merit_Scorecard!$I$7:$I$106,Merit_Scorecard!$C$7:$C$106,$A15)) -> 0 | I15: =IF($A15="","",COUNTIFS(Recognition_Log!$E$5:$E$304,$A15,Recognition_Log!$H$5:$H$304,"Yes",Recognition_Log!$N$5:$N$304,"Approved",Recognition_Log!$O$5:$O$304,">="&Merit_Scorecard!$B$3,Recognition_Log!$O$5:$O$304,"<="&Merit_Scorecard!$B$4)) -> 0 | J15: =IF($A15="","",COUNTIFS(Recognition_Log!$G$5:$G$304,$A15,Recognition_Log!$H$5:$H$304,"Yes",Recognition_Log!$N$5:$N$304,"Approved",Recognition_Log!$O$5:$O$304,">="&Merit_Scorecard!$B$3,Recognition_Log!$O$5:$O$304,"<="&Merit_Scorecard!$B$4)) -> 0 | K15: =IF($A15="","",COUNTIFS(Corrective_Action_Log!$E$5:$E$304,$A15,Corrective_Action_Log!$N$5:$N$304,">="&Merit_Scorecard!$B$3,Corrective_Action_Log!$N$5:$N$304,"<="&Merit_Scorecard!$B$4)) -> 0 | L15: =IF($A15="","",SUMIFS(Merit_Scorecard!$J$7:$J$106,Merit_Scorecard!$C$7:$C$106,$A15)) -> 0 | M15: =IF($A15="","",SUMIFS(Merit_Scorecard!$K$7:$K$106,Merit_Scorecard!$C$7:$C$106,$A15)) -> 0 | N15: =IF($A15="","",IFERROR(AVERAGEIF(Merit_Scorecard!$C$7:$C$106,$A15,Merit_Scorecard!$L$7:$L$106),0)) -> 0
A16: =IF(Reference_Data!A11="","",Reference_Data!A11) | B16: =IF($A16="","",COUNTIFS(Employee_Master!$C$5:$C$104,$A16,Employee_Master!$H$5:$H$104,"Active")) | C16: =IF($A16="","",SUMIFS(Merit_Scorecard!$D$7:$D$106,Merit_Scorecard!$C$7:$C$106,$A16)) | D16: =IF($A16="","",SUMIFS(Merit_Scorecard!$E$7:$E$106,Merit_Scorecard!$C$7:$C$106,$A16)) | E16: =IF($A16="","",SUMIFS(Merit_Scorecard!$F$7:$F$106,Merit_Scorecard!$C$7:$C$106,$A16)) | F16: =IF($A16="","",SUMIFS(Merit_Scorecard!$G$7:$G$106,Merit_Scorecard!$C$7:$C$106,$A16)) | G16: =IF($A16="","",SUMIFS(Merit_Scorecard!$H$7:$H$106,Merit_Scorecard!$C$7:$C$106,$A16)) | H16: =IF($A16="","",SUMIFS(Merit_Scorecard!$I$7:$I$106,Merit_Scorecard!$C$7:$C$106,$A16)) | I16: =IF($A16="","",COUNTIFS(Recognition_Log!$E$5:$E$304,$A16,Recognition_Log!$H$5:$H$304,"Yes",Recognition_Log!$N$5:$N$304,"Approved",Recognition_Log!$O$5:$O$304,">="&Merit_Scorecard!$B$3,Recognition_Log!$O$5:$O$304,"<="&Merit_Scorecard!$B$4)) | J16: =IF($A16="","",COUNTIFS(Recognition_Log!$G$5:$G$304,$A16,Recognition_Log!$H$5:$H$304,"Yes",Recognition_Log!$N$5:$N$304,"Approved",Recognition_Log!$O$5:$O$304,">="&Merit_Scorecard!$B$3,Recognition_Log!$O$5:$O$304,"<="&Merit_Scorecard!$B$4)) | K16: =IF($A16="","",COUNTIFS(Corrective_Action_Log!$E$5:$E$304,$A16,Corrective_Action_Log!$N$5:$N$304,">="&Merit_Scorecard!$B$3,Corrective_Action_Log!$N$5:$N$304,"<="&Merit_Scorecard!$B$4)) | L16: =IF($A16="","",SUMIFS(Merit_Scorecard!$J$7:$J$106,Merit_Scorecard!$C$7:$C$106,$A16)) | M16: =IF($A16="","",SUMIFS(Merit_Scorecard!$K$7:$K$106,Merit_Scorecard!$C$7:$C$106,$A16)) | N16: =IF($A16="","",IFERROR(AVERAGEIF(Merit_Scorecard!$C$7:$C$106,$A16,Merit_Scorecard!$L$7:$L$106),0))
A17: =IF(Reference_Data!A12="","",Reference_Data!A12) | B17: =IF($A17="","",COUNTIFS(Employee_Master!$C$5:$C$104,$A17,Employee_Master!$H$5:$H$104,"Active")) | C17: =IF($A17="","",SUMIFS(Merit_Scorecard!$D$7:$D$106,Merit_Scorecard!$C$7:$C$106,$A17)) | D17: =IF($A17="","",SUMIFS(Merit_Scorecard!$E$7:$E$106,Merit_Scorecard!$C$7:$C$106,$A17)) | E17: =IF($A17="","",SUMIFS(Merit_Scorecard!$F$7:$F$106,Merit_Scorecard!$C$7:$C$106,$A17)) | F17: =IF($A17="","",SUMIFS(Merit_Scorecard!$G$7:$G$106,Merit_Scorecard!$C$7:$C$106,$A17)) | G17: =IF($A17="","",SUMIFS(Merit_Scorecard!$H$7:$H$106,Merit_Scorecard!$C$7:$C$106,$A17)) | H17: =IF($A17="","",SUMIFS(Merit_Scorecard!$I$7:$I$106,Merit_Scorecard!$C$7:$C$106,$A17)) | I17: =IF($A17="","",COUNTIFS(Recognition_Log!$E$5:$E$304,$A17,Recognition_Log!$H$5:$H$304,"Yes",Recognition_Log!$N$5:$N$304,"Approved",Recognition_Log!$O$5:$O$304,">="&Merit_Scorecard!$B$3,Recognition_Log!$O$5:$O$304,"<="&Merit_Scorecard!$B$4)) | J17: =IF($A17="","",COUNTIFS(Recognition_Log!$G$5:$G$304,$A17,Recognition_Log!$H$5:$H$304,"Yes",Recognition_Log!$N$5:$N$304,"Approved",Recognition_Log!$O$5:$O$304,">="&Merit_Scorecard!$B$3,Recognition_Log!$O$5:$O$304,"<="&Merit_Scorecard!$B$4)) | K17: =IF($A17="","",COUNTIFS(Corrective_Action_Log!$E$5:$E$304,$A17,Corrective_Action_Log!$N$5:$N$304,">="&Merit_Scorecard!$B$3,Corrective_Action_Log!$N$5:$N$304,"<="&Merit_Scorecard!$B$4)) | L17: =IF($A17="","",SUMIFS(Merit_Scorecard!$J$7:$J$106,Merit_Scorecard!$C$7:$C$106,$A17)) | M17: =IF($A17="","",SUMIFS(Merit_Scorecard!$K$7:$K$106,Merit_Scorecard!$C$7:$C$106,$A17)) | N17: =IF($A17="","",IFERROR(AVERAGEIF(Merit_Scorecard!$C$7:$C$106,$A17,Merit_Scorecard!$L$7:$L$106),0))
A18: =IF(Reference_Data!A13="","",Reference_Data!A13) | B18: =IF($A18="","",COUNTIFS(Employee_Master!$C$5:$C$104,$A18,Employee_Master!$H$5:$H$104,"Active")) | C18: =IF($A18="","",SUMIFS(Merit_Scorecard!$D$7:$D$106,Merit_Scorecard!$C$7:$C$106,$A18)) | D18: =IF($A18="","",SUMIFS(Merit_Scorecard!$E$7:$E$106,Merit_Scorecard!$C$7:$C$106,$A18)) | E18: =IF($A18="","",SUMIFS(Merit_Scorecard!$F$7:$F$106,Merit_Scorecard!$C$7:$C$106,$A18)) | F18: =IF($A18="","",SUMIFS(Merit_Scorecard!$G$7:$G$106,Merit_Scorecard!$C$7:$C$106,$A18)) | G18: =IF($A18="","",SUMIFS(Merit_Scorecard!$H$7:$H$106,Merit_Scorecard!$C$7:$C$106,$A18)) | H18: =IF($A18="","",SUMIFS(Merit_Scorecard!$I$7:$I$106,Merit_Scorecard!$C$7:$C$106,$A18)) | I18: =IF($A18="","",COUNTIFS(Recognition_Log!$E$5:$E$304,$A18,Recognition_Log!$H$5:$H$304,"Yes",Recognition_Log!$N$5:$N$304,"Approved",Recognition_Log!$O$5:$O$304,">="&Merit_Scorecard!$B$3,Recognition_Log!$O$5:$O$304,"<="&Merit_Scorecard!$B$4)) | J18: =IF($A18="","",COUNTIFS(Recognition_Log!$G$5:$G$304,$A18,Recognition_Log!$H$5:$H$304,"Yes",Recognition_Log!$N$5:$N$304,"Approved",Recognition_Log!$O$5:$O$304,">="&Merit_Scorecard!$B$3,Recognition_Log!$O$5:$O$304,"<="&Merit_Scorecard!$B$4)) | K18: =IF($A18="","",COUNTIFS(Corrective_Action_Log!$E$5:$E$304,$A18,Corrective_Action_Log!$N$5:$N$304,">="&Merit_Scorecard!$B$3,Corrective_Action_Log!$N$5:$N$304,"<="&Merit_Scorecard!$B$4)) | L18: =IF($A18="","",SUMIFS(Merit_Scorecard!$J$7:$J$106,Merit_Scorecard!$C$7:$C$106,$A18)) | M18: =IF($A18="","",SUMIFS(Merit_Scorecard!$K$7:$K$106,Merit_Scorecard!$C$7:$C$106,$A18)) | N18: =IF($A18="","",IFERROR(AVERAGEIF(Merit_Scorecard!$C$7:$C$106,$A18,Merit_Scorecard!$L$7:$L$106),0))
A19: =IF(Reference_Data!A14="","",Reference_Data!A14) | B19: =IF($A19="","",COUNTIFS(Employee_Master!$C$5:$C$104,$A19,Employee_Master!$H$5:$H$104,"Active")) | C19: =IF($A19="","",SUMIFS(Merit_Scorecard!$D$7:$D$106,Merit_Scorecard!$C$7:$C$106,$A19)) | D19: =IF($A19="","",SUMIFS(Merit_Scorecard!$E$7:$E$106,Merit_Scorecard!$C$7:$C$106,$A19)) | E19: =IF($A19="","",SUMIFS(Merit_Scorecard!$F$7:$F$106,Merit_Scorecard!$C$7:$C$106,$A19)) | F19: =IF($A19="","",SUMIFS(Merit_Scorecard!$G$7:$G$106,Merit_Scorecard!$C$7:$C$106,$A19)) | G19: =IF($A19="","",SUMIFS(Merit_Scorecard!$H$7:$H$106,Merit_Scorecard!$C$7:$C$106,$A19)) | H19: =IF($A19="","",SUMIFS(Merit_Scorecard!$I$7:$I$106,Merit_Scorecard!$C$7:$C$106,$A19)) | I19: =IF($A19="","",COUNTIFS(Recognition_Log!$E$5:$E$304,$A19,Recognition_Log!$H$5:$H$304,"Yes",Recognition_Log!$N$5:$N$304,"Approved",Recognition_Log!$O$5:$O$304,">="&Merit_Scorecard!$B$3,Recognition_Log!$O$5:$O$304,"<="&Merit_Scorecard!$B$4)) | J19: =IF($A19="","",COUNTIFS(Recognition_Log!$G$5:$G$304,$A19,Recognition_Log!$H$5:$H$304,"Yes",Recognition_Log!$N$5:$N$304,"Approved",Recognition_Log!$O$5:$O$304,">="&Merit_Scorecard!$B$3,Recognition_Log!$O$5:$O$304,"<="&Merit_Scorecard!$B$4)) | K19: =IF($A19="","",COUNTIFS(Corrective_Action_Log!$E$5:$E$304,$A19,Corrective_Action_Log!$N$5:$N$304,">="&Merit_Scorecard!$B$3,Corrective_Action_Log!$N$5:$N$304,"<="&Merit_Scorecard!$B$4)) | L19: =IF($A19="","",SUMIFS(Merit_Scorecard!$J$7:$J$106,Merit_Scorecard!$C$7:$C$106,$A19)) | M19: =IF($A19="","",SUMIFS(Merit_Scorecard!$K$7:$K$106,Merit_Scorecard!$C$7:$C$106,$A19)) | N19: =IF($A19="","",IFERROR(AVERAGEIF(Merit_Scorecard!$C$7:$C$106,$A19,Merit_Scorecard!$L$7:$L$106),0))
A21: Cost of Quality by Category
A22: COQ Category | B22: Amount (PHP) | C22: Share
A23: =Reference_Data!L5 -> Prevention | B23: =SUMIFS(Qualification_Log!$N$5:$N$304,Qualification_Log!$L$5:$L$304,A23,Qualification_Log!$B$5:$B$304,">="&Merit_Scorecard!$B$3,Qualification_Log!$B$5:$B$304,"<="&Merit_Scorecard!$B$4) -> 8000 | C23: =IF(SUM($B$23:$B$26)=0,0,B23/SUM($B$23:$B$26)) -> 0.097560976
A24: =Reference_Data!L6 -> Appraisal | B24: =SUMIFS(Qualification_Log!$N$5:$N$304,Qualification_Log!$L$5:$L$304,A24,Qualification_Log!$B$5:$B$304,">="&Merit_Scorecard!$B$3,Qualification_Log!$B$5:$B$304,"<="&Merit_Scorecard!$B$4) -> 1500 | C24: =IF(SUM($B$23:$B$26)=0,0,B24/SUM($B$23:$B$26)) -> 0.018292683
A25: =Reference_Data!L7 -> Internal Failure | B25: =SUMIFS(Qualification_Log!$N$5:$N$304,Qualification_Log!$L$5:$L$304,A25,Qualification_Log!$B$5:$B$304,">="&Merit_Scorecard!$B$3,Qualification_Log!$B$5:$B$304,"<="&Merit_Scorecard!$B$4) -> 6000 | C25: =IF(SUM($B$23:$B$26)=0,0,B25/SUM($B$23:$B$26)) -> 0.073170732
A26: =Reference_Data!L8 -> External Failure | B26: =SUMIFS(Qualification_Log!$N$5:$N$304,Qualification_Log!$L$5:$L$304,A26,Qualification_Log!$B$5:$B$304,">="&Merit_Scorecard!$B$3,Qualification_Log!$B$5:$B$304,"<="&Merit_Scorecard!$B$4) -> 66500 | C26: =IF(SUM($B$23:$B$26)=0,0,B26/SUM($B$23:$B$26)) -> 0.81097561
A27: Total | B27: =SUM(B23:B26) -> 82000
A28: Cost of Poor Quality (Internal + External Failure) | C28: =B25+B26 -> 72500

Sheet Merit_Scorecard
A1: Merit Scorecard
A2: Auto-calculated per employee for the review period. Only the two yellow period cells are inputs.
A3: Period Start | B3: 46023 | D3: Net Merit Score = Merit Points (approved recognitions) − Demerit Points (decided corrective actions). Any Critical incident or decertification in the period sets Standing to 'Under Review' regardless of score.
A4: Period End | B4: 46387
A6: Employee ID | B6: Employee Name | C6: Department | D6: Active Certifications | E6: Decertifications | F6: Quality Incidents | G6: Critical Incidents | H6: Cost of Quality (PHP) | I6: Recognitions | J6: Merit Points | K6: Demerit Points | L6: Net Merit Score | M6: Performance Standing | N6: Reward Eligibility | O6: Rank
A7: =IF(Employee_Master!A5="","",Employee_Master!A5) -> E-1001 | B7: =IF($A7="","",Employee_Master!B5) -> Andrea Villanueva | C7: =IF($A7="","",Employee_Master!C5) -> Design | D7: =IF($A7="","",COUNTIFS(Qualification_Log!$C$5:$C$304,$A7,Qualification_Log!$U$5:$U$304,"Active")) -> 2 | E7: =IF($A7="","",COUNTIFS(Qualification_Log!$C$5:$C$304,$A7,Qualification_Log!$Q$5:$Q$304,"Yes",Qualification_Log!$R$5:$R$304,">="&$B$3,Qualification_Log!$R$5:$R$304,"<="&$B$4)) -> 0 | F7: =IF($A7="","",COUNTIFS(Qualification_Log!$C$5:$C$304,$A7,Qualification_Log!$G$5:$G$304,"Quality Incident",Qualification_Log!$B$5:$B$304,">="&$B$3,Qualification_Log!$B$5:$B$304,"<="&$B$4)+COUNTIFS(Qualification_Log!$C$5:$C$304,$A7,Qualification_Log!$G$5:$G$304,"Decertification",Qualification_Log!$O$5:$O$304,"<>",Qualification_Log!$B$5:$B$304,">="&$B$3,Qualification_Log!$B$5:$B$304,"<="&$B$4)) -> 0 | G7: =IF($A7="","",COUNTIFS(Qualification_Log!$C$5:$C$304,$A7,Qualification_Log!$O$5:$O$304,"Critical",Qualification_Log!$B$5:$B$304,">="&$B$3,Qualification_Log!$B$5:$B$304,"<="&$B$4)) -> 0 | H7: =IF($A7="","",SUMIFS(Qualification_Log!$N$5:$N$304,Qualification_Log!$C$5:$C$304,$A7,Qualification_Log!$B$5:$B$304,">="&$B$3,Qualification_Log!$B$5:$B$304,"<="&$B$4)) -> 0 | I7: =IF($A7="","",COUNTIFS(Recognition_Log!$C$5:$C$304,$A7,Recognition_Log!$N$5:$N$304,"Approved",Recognition_Log!$O$5:$O$304,">="&$B$3,Recognition_Log!$O$5:$O$304,"<="&$B$4)) -> 2 | J7: =IF($A7="","",SUMIFS(Recognition_Log!$Q$5:$Q$304,Recognition_Log!$C$5:$C$304,$A7,Recognition_Log!$O$5:$O$304,">="&$B$3,Recognition_Log!$O$5:$O$304,"<="&$B$4)) -> 45 | K7: =IF($A7="","",SUMIFS(Corrective_Action_Log!$T$5:$T$304,Corrective_Action_Log!$C$5:$C$304,$A7,Corrective_Action_Log!$N$5:$N$304,">="&$B$3,Corrective_Action_Log!$N$5:$N$304,"<="&$B$4)) -> 0 | L7: =IF($A7="","",J7-K7) -> 45 | M7: =IF($A7="","",IF(OR(G7>0,E7>0),"Under Review",IF(L7>=Reference_Data!$AL$7,"Exemplary",IF(L7>=Reference_Data!$AL$8,"Commendable",IF(L7>=Reference_Data!$AL$9,"Meets Standard","Needs Improvement"))))) -> Exemplary | N7: =IF($A7="","",IF(OR(G7>0,K7>=Reference_Data!$AL$10),"Ineligible","Eligible")) -> Eligible | O7: =IF($A7="","",RANK(L7,$L$7:$L$106)) -> 1
A8: =IF(Employee_Master!A6="","",Employee_Master!A6) -> E-1002 | B8: =IF($A8="","",Employee_Master!B6) -> Carlo Mendoza | C8: =IF($A8="","",Employee_Master!C6) -> Design | D8: =IF($A8="","",COUNTIFS(Qualification_Log!$C$5:$C$304,$A8,Qualification_Log!$U$5:$U$304,"Active")) -> 1 | E8: =IF($A8="","",COUNTIFS(Qualification_Log!$C$5:$C$304,$A8,Qualification_Log!$Q$5:$Q$304,"Yes",Qualification_Log!$R$5:$R$304,">="&$B$3,Qualification_Log!$R$5:$R$304,"<="&$B$4)) -> 0 | F8: =IF($A8="","",COUNTIFS(Qualification_Log!$C$5:$C$304,$A8,Qualification_Log!$G$5:$G$304,"Quality Incident",Qualification_Log!$B$5:$B$304,">="&$B$3,Qualification_Log!$B$5:$B$304,"<="&$B$4)+COUNTIFS(Qualification_Log!$C$5:$C$304,$A8,Qualification_Log!$G$5:$G$304,"Decertification",Qualification_Log!$O$5:$O$304,"<>",Qualification_Log!$B$5:$B$304,">="&$B$3,Qualification_Log!$B$5:$B$304,"<="&$B$4)) -> 1 | G8: =IF($A8="","",COUNTIFS(Qualification_Log!$C$5:$C$304,$A8,Qualification_Log!$O$5:$O$304,"Critical",Qualification_Log!$B$5:$B$304,">="&$B$3,Qualification_Log!$B$5:$B$304,"<="&$B$4)) -> 0 | H8: =IF($A8="","",SUMIFS(Qualification_Log!$N$5:$N$304,Qualification_Log!$C$5:$C$304,$A8,Qualification_Log!$B$5:$B$304,">="&$B$3,Qualification_Log!$B$5:$B$304,"<="&$B$4)) -> 3500 | I8: =IF($A8="","",COUNTIFS(Recognition_Log!$C$5:$C$304,$A8,Recognition_Log!$N$5:$N$304,"Approved",Recognition_Log!$O$5:$O$304,">="&$B$3,Recognition_Log!$O$5:$O$304,"<="&$B$4)) -> 1 | J8: =IF($A8="","",SUMIFS(Recognition_Log!$Q$5:$Q$304,Recognition_Log!$C$5:$C$304,$A8,Recognition_Log!$O$5:$O$304,">="&$B$3,Recognition_Log!$O$5:$O$304,"<="&$B$4)) -> 15 | K8: =IF($A8="","",SUMIFS(Corrective_Action_Log!$T$5:$T$304,Corrective_Action_Log!$C$5:$C$304,$A8,Corrective_Action_Log!$N$5:$N$304,">="&$B$3,Corrective_Action_Log!$N$5:$N$304,"<="&$B$4)) -> 0 | L8: =IF($A8="","",J8-K8) -> 15 | M8: =IF($A8="","",IF(OR(G8>0,E8>0),"Under Review",IF(L8>=Reference_Data!$AL$7,"Exemplary",IF(L8>=Reference_Data!$AL$8,"Commendable",IF(L8>=Reference_Data!$AL$9,"Meets Standard","Needs Improvement"))))) -> Commendable | N8: =IF($A8="","",IF(OR(G8>0,K8>=Reference_Data!$AL$10),"Ineligible","Eligible")) -> Eligible | O8: =IF($A8="","",RANK(L8,$L$7:$L$106)) -> 3
A9: =IF(Employee_Master!A7="","",Employee_Master!A7) -> E-1003 | B9: =IF($A9="","",Employee_Master!B7) -> Bea Santos | C9: =IF($A9="","",Employee_Master!C7) -> Permitting | D9: =IF($A9="","",COUNTIFS(Qualification_Log!$C$5:$C$304,$A9,Qualification_Log!$U$5:$U$304,"Active")) -> 0 | E9: =IF($A9="","",COUNTIFS(Qualification_Log!$C$5:$C$304,$A9,Qualification_Log!$Q$5:$Q$304,"Yes",Qualification_Log!$R$5:$R$304,">="&$B$3,Qualification_Log!$R$5:$R$304,"<="&$B$4)) -> 0 | F9: =IF($A9="","",COUNTIFS(Qualification_Log!$C$5:$C$304,$A9,Qualification_Log!$G$5:$G$304,"Quality Incident",Qualification_Log!$B$5:$B$304,">="&$B$3,Qualification_Log!$B$5:$B$304,"<="&$B$4)+COUNTIFS(Qualification_Log!$C$5:$C$304,$A9,Qualification_Log!$G$5:$G$304,"Decertification",Qualification_Log!$O$5:$O$304,"<>",Qualification_Log!$B$5:$B$304,">="&$B$3,Qualification_Log!$B$5:$B$304,"<="&$B$4)) -> 0 | G9: =IF($A9="","",COUNTIFS(Qualification_Log!$C$5:$C$304,$A9,Qualification_Log!$O$5:$O$304,"Critical",Qualification_Log!$B$5:$B$304,">="&$B$3,Qualification_Log!$B$5:$B$304,"<="&$B$4)) -> 0 | H9: =IF($A9="","",SUMIFS(Qualification_Log!$N$5:$N$304,Qualification_Log!$C$5:$C$304,$A9,Qualification_Log!$B$5:$B$304,">="&$B$3,Qualification_Log!$B$5:$B$304,"<="&$B$4)) -> 0 | I9: =IF($A9="","",COUNTIFS(Recognition_Log!$C$5:$C$304,$A9,Recognition_Log!$N$5:$N$304,"Approved",Recognition_Log!$O$5:$O$304,">="&$B$3,Recognition_Log!$O$5:$O$304,"<="&$B$4)) -> 1 | J9: =IF($A9="","",SUMIFS(Recognition_Log!$Q$5:$Q$304,Recognition_Log!$C$5:$C$304,$A9,Recognition_Log!$O$5:$O$304,">="&$B$3,Recognition_Log!$O$5:$O$304,"<="&$B$4)) -> 10 | K9: =IF($A9="","",SUMIFS(Corrective_Action_Log!$T$5:$T$304,Corrective_Action_Log!$C$5:$C$304,$A9,Corrective_Action_Log!$N$5:$N$304,">="&$B$3,Corrective_Action_Log!$N$5:$N$304,"<="&$B$4)) -> 0 | L9: =IF($A9="","",J9-K9) -> 10 | M9: =IF($A9="","",IF(OR(G9>0,E9>0),"Under Review",IF(L9>=Reference_Data!$AL$7,"Exemplary",IF(L9>=Reference_Data!$AL$8,"Commendable",IF(L9>=Reference_Data!$AL$9,"Meets Standard","Needs Improvement"))))) -> Meets Standard | N9: =IF($A9="","",IF(OR(G9>0,K9>=Reference_Data!$AL$10),"Ineligible","Eligible")) -> Eligible | O9: =IF($A9="","",RANK(L9,$L$7:$L$106)) -> 6
A10: =IF(Employee_Master!A8="","",Employee_Master!A8) -> E-1004 | B10: =IF($A10="","",Employee_Master!B8) -> Daniel Reyes | C10: =IF($A10="","",Employee_Master!C8) -> Permitting | D10: =IF($A10="","",COUNTIFS(Qualification_Log!$C$5:$C$304,$A10,Qualification_Log!$U$5:$U$304,"Active")) -> 1 | E10: =IF($A10="","",COUNTIFS(Qualification_Log!$C$5:$C$304,$A10,Qualification_Log!$Q$5:$Q$304,"Yes",Qualification_Log!$R$5:$R$304,">="&$B$3,Qualification_Log!$R$5:$R$304,"<="&$B$4)) -> 0 | F10: =IF($A10="","",COUNTIFS(Qualification_Log!$C$5:$C$304,$A10,Qualification_Log!$G$5:$G$304,"Quality Incident",Qualification_Log!$B$5:$B$304,">="&$B$3,Qualification_Log!$B$5:$B$304,"<="&$B$4)+COUNTIFS(Qualification_Log!$C$5:$C$304,$A10,Qualification_Log!$G$5:$G$304,"Decertification",Qualification_Log!$O$5:$O$304,"<>",Qualification_Log!$B$5:$B$304,">="&$B$3,Qualification_Log!$B$5:$B$304,"<="&$B$4)) -> 1 | G10: =IF($A10="","",COUNTIFS(Qualification_Log!$C$5:$C$304,$A10,Qualification_Log!$O$5:$O$304,"Critical",Qualification_Log!$B$5:$B$304,">="&$B$3,Qualification_Log!$B$5:$B$304,"<="&$B$4)) -> 0 | H10: =IF($A10="","",SUMIFS(Qualification_Log!$N$5:$N$304,Qualification_Log!$C$5:$C$304,$A10,Qualification_Log!$B$5:$B$304,">="&$B$3,Qualification_Log!$B$5:$B$304,"<="&$B$4)) -> 9500 | I10: =IF($A10="","",COUNTIFS(Recognition_Log!$C$5:$C$304,$A10,Recognition_Log!$N$5:$N$304,"Approved",Recognition_Log!$O$5:$O$304,">="&$B$3,Recognition_Log!$O$5:$O$304,"<="&$B$4)) -> 0 | J10: =IF($A10="","",SUMIFS(Recognition_Log!$Q$5:$Q$304,Recognition_Log!$C$5:$C$304,$A10,Recognition_Log!$O$5:$O$304,">="&$B$3,Recognition_Log!$O$5:$O$304,"<="&$B$4)) -> 0 | K10: =IF($A10="","",SUMIFS(Corrective_Action_Log!$T$5:$T$304,Corrective_Action_Log!$C$5:$C$304,$A10,Corrective_Action_Log!$N$5:$N$304,">="&$B$3,Corrective_Action_Log!$N$5:$N$304,"<="&$B$4)) -> 0 | L10: =IF($A10="","",J10-K10) -> 0 | M10: =IF($A10="","",IF(OR(G10>0,E10>0),"Under Review",IF(L10>=Reference_Data!$AL$7,"Exemplary",IF(L10>=Reference_Data!$AL$8,"Commendable",IF(L10>=Reference_Data!$AL$9,"Meets Standard","Needs Improvement"))))) -> Meets Standard | N10: =IF($A10="","",IF(OR(G10>0,K10>=Reference_Data!$AL$10),"Ineligible","Eligible")) -> Eligible | O10: =IF($A10="","",RANK(L10,$L$7:$L$106)) -> 7
A11: =IF(Employee_Master!A9="","",Employee_Master!A9) -> E-1005 | B11: =IF($A11="","",Employee_Master!B9) -> Ella Navarro | C11: =IF($A11="","",Employee_Master!C9) -> Interconnection | D11: =IF($A11="","",COUNTIFS(Qualification_Log!$C$5:$C$304,$A11,Qualification_Log!$U$5:$U$304,"Active")) -> 1 | E11: =IF($A11="","",COUNTIFS(Qualification_Log!$C$5:$C$304,$A11,Qualification_Log!$Q$5:$Q$304,"Yes",Qualification_Log!$R$5:$R$304,">="&$B$3,Qualification_Log!$R$5:$R$304,"<="&$B$4)) -> 0 | F11: =IF($A11="","",COUNTIFS(Qualification_Log!$C$5:$C$304,$A11,Qualification_Log!$G$5:$G$304,"Quality Incident",Qualification_Log!$B$5:$B$304,">="&$B$3,Qualification_Log!$B$5:$B$304,"<="&$B$4)+COUNTIFS(Qualification_Log!$C$5:$C$304,$A11,Qualification_Log!$G$5:$G$304,"Decertification",Qualification_Log!$O$5:$O$304,"<>",Qualification_Log!$B$5:$B$304,">="&$B$3,Qualification_Log!$B$5:$B$304,"<="&$B$4)) -> 0 | G11: =IF($A11="","",COUNTIFS(Qualification_Log!$C$5:$C$304,$A11,Qualification_Log!$O$5:$O$304,"Critical",Qualification_Log!$B$5:$B$304,">="&$B$3,Qualification_Log!$B$5:$B$304,"<="&$B$4)) -> 0 | H11: =IF($A11="","",SUMIFS(Qualification_Log!$N$5:$N$304,Qualification_Log!$C$5:$C$304,$A11,Qualification_Log!$B$5:$B$304,">="&$B$3,Qualification_Log!$B$5:$B$304,"<="&$B$4)) -> 0 | I11: =IF($A11="","",COUNTIFS(Recognition_Log!$C$5:$C$304,$A11,Recognition_Log!$N$5:$N$304,"Approved",Recognition_Log!$O$5:$O$304,">="&$B$3,Recognition_Log!$O$5:$O$304,"<="&$B$4)) -> 1 | J11: =IF($A11="","",SUMIFS(Recognition_Log!$Q$5:$Q$304,Recognition_Log!$C$5:$C$304,$A11,Recognition_Log!$O$5:$O$304,">="&$B$3,Recognition_Log!$O$5:$O$304,"<="&$B$4)) -> 15 | K11: =IF($A11="","",SUMIFS(Corrective_Action_Log!$T$5:$T$304,Corrective_Action_Log!$C$5:$C$304,$A11,Corrective_Action_Log!$N$5:$N$304,">="&$B$3,Corrective_Action_Log!$N$5:$N$304,"<="&$B$4)) -> 0 | L11: =IF($A11="","",J11-K11) -> 15 | M11: =IF($A11="","",IF(OR(G11>0,E11>0),"Under Review",IF(L11>=Reference_Data!$AL$7,"Exemplary",IF(L11>=Reference_Data!$AL$8,"Commendable",IF(L11>=Reference_Data!$AL$9,"Meets Standard","Needs Improvement"))))) -> Commendable | N11: =IF($A11="","",IF(OR(G11>0,K11>=Reference_Data!$AL$10),"Ineligible","Eligible")) -> Eligible | O11: =IF($A11="","",RANK(L11,$L$7:$L$106)) -> 3
A12: =IF(Employee_Master!A10="","",Employee_Master!A10) -> E-1006 | B12: =IF($A12="","",Employee_Master!B10) -> Francis Aquino | C12: =IF($A12="","",Employee_Master!C10) -> Interconnection | D12: =IF($A12="","",COUNTIFS(Qualification_Log!$C$5:$C$304,$A12,Qualification_Log!$U$5:$U$304,"Active")) -> 1 | E12: =IF($A12="","",COUNTIFS(Qualification_Log!$C$5:$C$304,$A12,Qualification_Log!$Q$5:$Q$304,"Yes",Qualification_Log!$R$5:$R$304,">="&$B$3,Qualification_Log!$R$5:$R$304,"<="&$B$4)) -> 0 | F12: =IF($A12="","",COUNTIFS(Qualification_Log!$C$5:$C$304,$A12,Qualification_Log!$G$5:$G$304,"Quality Incident",Qualification_Log!$B$5:$B$304,">="&$B$3,Qualification_Log!$B$5:$B$304,"<="&$B$4)+COUNTIFS(Qualification_Log!$C$5:$C$304,$A12,Qualification_Log!$G$5:$G$304,"Decertification",Qualification_Log!$O$5:$O$304,"<>",Qualification_Log!$B$5:$B$304,">="&$B$3,Qualification_Log!$B$5:$B$304,"<="&$B$4)) -> 1 | G12: =IF($A12="","",COUNTIFS(Qualification_Log!$C$5:$C$304,$A12,Qualification_Log!$O$5:$O$304,"Critical",Qualification_Log!$B$5:$B$304,">="&$B$3,Qualification_Log!$B$5:$B$304,"<="&$B$4)) -> 0 | H12: =IF($A12="","",SUMIFS(Qualification_Log!$N$5:$N$304,Qualification_Log!$C$5:$C$304,$A12,Qualification_Log!$B$5:$B$304,">="&$B$3,Qualification_Log!$B$5:$B$304,"<="&$B$4)) -> 2500 | I12: =IF($A12="","",COUNTIFS(Recognition_Log!$C$5:$C$304,$A12,Recognition_Log!$N$5:$N$304,"Approved",Recognition_Log!$O$5:$O$304,">="&$B$3,Recognition_Log!$O$5:$O$304,"<="&$B$4)) -> 0 | J12: =IF($A12="","",SUMIFS(Recognition_Log!$Q$5:$Q$304,Recognition_Log!$C$5:$C$304,$A12,Recognition_Log!$O$5:$O$304,">="&$B$3,Recognition_Log!$O$5:$O$304,"<="&$B$4)) -> 0 | K12: =IF($A12="","",SUMIFS(Corrective_Action_Log!$T$5:$T$304,Corrective_Action_Log!$C$5:$C$304,$A12,Corrective_Action_Log!$N$5:$N$304,">="&$B$3,Corrective_Action_Log!$N$5:$N$304,"<="&$B$4)) -> 0 | L12: =IF($A12="","",J12-K12) -> 0 | M12: =IF($A12="","",IF(OR(G12>0,E12>0),"Under Review",IF(L12>=Reference_Data!$AL$7,"Exemplary",IF(L12>=Reference_Data!$AL$8,"Commendable",IF(L12>=Reference_Data!$AL$9,"Meets Standard","Needs Improvement"))))) -> Meets Standard | N12: =IF($A12="","",IF(OR(G12>0,K12>=Reference_Data!$AL$10),"Ineligible","Eligible")) -> Eligible | O12: =IF($A12="","",RANK(L12,$L$7:$L$106)) -> 7
A13: =IF(Employee_Master!A11="","",Employee_Master!A11) -> E-1007 | B13: =IF($A13="","",Employee_Master!B11) -> Grace Bautista | C13: =IF($A13="","",Employee_Master!C11) -> Quality Assurance | D13: =IF($A13="","",COUNTIFS(Qualification_Log!$C$5:$C$304,$A13,Qualification_Log!$U$5:$U$304,"Active")) -> 1 | E13: =IF($A13="","",COUNTIFS(Qualification_Log!$C$5:$C$304,$A13,Qualification_Log!$Q$5:$Q$304,"Yes",Qualification_Log!$R$5:$R$304,">="&$B$3,Qualification_Log!$R$5:$R$304,"<="&$B$4)) -> 0 | F13: =IF($A13="","",COUNTIFS(Qualification_Log!$C$5:$C$304,$A13,Qualification_Log!$G$5:$G$304,"Quality Incident",Qualification_Log!$B$5:$B$304,">="&$B$3,Qualification_Log!$B$5:$B$304,"<="&$B$4)+COUNTIFS(Qualification_Log!$C$5:$C$304,$A13,Qualification_Log!$G$5:$G$304,"Decertification",Qualification_Log!$O$5:$O$304,"<>",Qualification_Log!$B$5:$B$304,">="&$B$3,Qualification_Log!$B$5:$B$304,"<="&$B$4)) -> 0 | G13: =IF($A13="","",COUNTIFS(Qualification_Log!$C$5:$C$304,$A13,Qualification_Log!$O$5:$O$304,"Critical",Qualification_Log!$B$5:$B$304,">="&$B$3,Qualification_Log!$B$5:$B$304,"<="&$B$4)) -> 0 | H13: =IF($A13="","",SUMIFS(Qualification_Log!$N$5:$N$304,Qualification_Log!$C$5:$C$304,$A13,Qualification_Log!$B$5:$B$304,">="&$B$3,Qualification_Log!$B$5:$B$304,"<="&$B$4)) -> 1500 | I13: =IF($A13="","",COUNTIFS(Recognition_Log!$C$5:$C$304,$A13,Recognition_Log!$N$5:$N$304,"Approved",Recognition_Log!$O$5:$O$304,">="&$B$3,Recognition_Log!$O$5:$O$304,"<="&$B$4)) -> 1 | J13: =IF($A13="","",SUMIFS(Recognition_Log!$Q$5:$Q$304,Recognition_Log!$C$5:$C$304,$A13,Recognition_Log!$O$5:$O$304,">="&$B$3,Recognition_Log!$O$5:$O$304,"<="&$B$4)) -> 20 | K13: =IF($A13="","",SUMIFS(Corrective_Action_Log!$T$5:$T$304,Corrective_Action_Log!$C$5:$C$304,$A13,Corrective_Action_Log!$N$5:$N$304,">="&$B$3,Corrective_Action_Log!$N$5:$N$304,"<="&$B$4)) -> 0 | L13: =IF($A13="","",J13-K13) -> 20 | M13: =IF($A13="","",IF(OR(G13>0,E13>0),"Under Review",IF(L13>=Reference_Data!$AL$7,"Exemplary",IF(L13>=Reference_Data!$AL$8,"Commendable",IF(L13>=Reference_Data!$AL$9,"Meets Standard","Needs Improvement"))))) -> Commendable | N13: =IF($A13="","",IF(OR(G13>0,K13>=Reference_Data!$AL$10),"Ineligible","Eligible")) -> Eligible | O13: =IF($A13="","",RANK(L13,$L$7:$L$106)) -> 2
A14: =IF(Employee_Master!A12="","",Employee_Master!A12) -> E-1008 | B14: =IF($A14="","",Employee_Master!B12) -> Hector Lim | C14: =IF($A14="","",Employee_Master!C12) -> Quality Assurance | D14: =IF($A14="","",COUNTIFS(Qualification_Log!$C$5:$C$304,$A14,Qualification_Log!$U$5:$U$304,"Active")) -> 1 | E14: =IF($A14="","",COUNTIFS(Qualification_Log!$C$5:$C$304,$A14,Qualification_Log!$Q$5:$Q$304,"Yes",Qualification_Log!$R$5:$R$304,">="&$B$3,Qualification_Log!$R$5:$R$304,"<="&$B$4)) -> 0 | F14: =IF($A14="","",COUNTIFS(Qualification_Log!$C$5:$C$304,$A14,Qualification_Log!$G$5:$G$304,"Quality Incident",Qualification_Log!$B$5:$B$304,">="&$B$3,Qualification_Log!$B$5:$B$304,"<="&$B$4)+COUNTIFS(Qualification_Log!$C$5:$C$304,$A14,Qualification_Log!$G$5:$G$304,"Decertification",Qualification_Log!$O$5:$O$304,"<>",Qualification_Log!$B$5:$B$304,">="&$B$3,Qualification_Log!$B$5:$B$304,"<="&$B$4)) -> 0 | G14: =IF($A14="","",COUNTIFS(Qualification_Log!$C$5:$C$304,$A14,Qualification_Log!$O$5:$O$304,"Critical",Qualification_Log!$B$5:$B$304,">="&$B$3,Qualification_Log!$B$5:$B$304,"<="&$B$4)) -> 0 | H14: =IF($A14="","",SUMIFS(Qualification_Log!$N$5:$N$304,Qualification_Log!$C$5:$C$304,$A14,Qualification_Log!$B$5:$B$304,">="&$B$3,Qualification_Log!$B$5:$B$304,"<="&$B$4)) -> 8000 | I14: =IF($A14="","",COUNTIFS(Recognition_Log!$C$5:$C$304,$A14,Recognition_Log!$N$5:$N$304,"Approved",Recognition_Log!$O$5:$O$304,">="&$B$3,Recognition_Log!$O$5:$O$304,"<="&$B$4)) -> 1 | J14: =IF($A14="","",SUMIFS(Recognition_Log!$Q$5:$Q$304,Recognition_Log!$C$5:$C$304,$A14,Recognition_Log!$O$5:$O$304,">="&$B$3,Recognition_Log!$O$5:$O$304,"<="&$B$4)) -> 15 | K14: =IF($A14="","",SUMIFS(Corrective_Action_Log!$T$5:$T$304,Corrective_Action_Log!$C$5:$C$304,$A14,Corrective_Action_Log!$N$5:$N$304,">="&$B$3,Corrective_Action_Log!$N$5:$N$304,"<="&$B$4)) -> 0 | L14: =IF($A14="","",J14-K14) -> 15 | M14: =IF($A14="","",IF(OR(G14>0,E14>0),"Under Review",IF(L14>=Reference_Data!$AL$7,"Exemplary",IF(L14>=Reference_Data!$AL$8,"Commendable",IF(L14>=Reference_Data!$AL$9,"Meets Standard","Needs Improvement"))))) -> Commendable | N14: =IF($A14="","",IF(OR(G14>0,K14>=Reference_Data!$AL$10),"Ineligible","Eligible")) -> Eligible | O14: =IF($A14="","",RANK(L14,$L$7:$L$106)) -> 3
A15: =IF(Employee_Master!A13="","",Employee_Master!A13) -> E-1009 | B15: =IF($A15="","",Employee_Master!B13) -> Ivy Castillo | C15: =IF($A15="","",Employee_Master!C13) -> Project Management | D15: =IF($A15="","",COUNTIFS(Qualification_Log!$C$5:$C$304,$A15,Qualification_Log!$U$5:$U$304,"Active")) -> 0 | E15: =IF($A15="","",COUNTIFS(Qualification_Log!$C$5:$C$304,$A15,Qualification_Log!$Q$5:$Q$304,"Yes",Qualification_Log!$R$5:$R$304,">="&$B$3,Qualification_Log!$R$5:$R$304,"<="&$B$4)) -> 0 | F15: =IF($A15="","",COUNTIFS(Qualification_Log!$C$5:$C$304,$A15,Qualification_Log!$G$5:$G$304,"Quality Incident",Qualification_Log!$B$5:$B$304,">="&$B$3,Qualification_Log!$B$5:$B$304,"<="&$B$4)+COUNTIFS(Qualification_Log!$C$5:$C$304,$A15,Qualification_Log!$G$5:$G$304,"Decertification",Qualification_Log!$O$5:$O$304,"<>",Qualification_Log!$B$5:$B$304,">="&$B$3,Qualification_Log!$B$5:$B$304,"<="&$B$4)) -> 0 | G15: =IF($A15="","",COUNTIFS(Qualification_Log!$C$5:$C$304,$A15,Qualification_Log!$O$5:$O$304,"Critical",Qualification_Log!$B$5:$B$304,">="&$B$3,Qualification_Log!$B$5:$B$304,"<="&$B$4)) -> 0 | H15: =IF($A15="","",SUMIFS(Qualification_Log!$N$5:$N$304,Qualification_Log!$C$5:$C$304,$A15,Qualification_Log!$B$5:$B$304,">="&$B$3,Qualification_Log!$B$5:$B$304,"<="&$B$4)) -> 0 | I15: =IF($A15="","",COUNTIFS(Recognition_Log!$C$5:$C$304,$A15,Recognition_Log!$N$5:$N$304,"Approved",Recognition_Log!$O$5:$O$304,">="&$B$3,Recognition_Log!$O$5:$O$304,"<="&$B$4)) -> 0 | J15: =IF($A15="","",SUMIFS(Recognition_Log!$Q$5:$Q$304,Recognition_Log!$C$5:$C$304,$A15,Recognition_Log!$O$5:$O$304,">="&$B$3,Recognition_Log!$O$5:$O$304,"<="&$B$4)) -> 0 | K15: =IF($A15="","",SUMIFS(Corrective_Action_Log!$T$5:$T$304,Corrective_Action_Log!$C$5:$C$304,$A15,Corrective_Action_Log!$N$5:$N$304,">="&$B$3,Corrective_Action_Log!$N$5:$N$304,"<="&$B$4)) -> 5 | L15: =IF($A15="","",J15-K15) -> -5 | M15: =IF($A15="","",IF(OR(G15>0,E15>0),"Under Review",IF(L15>=Reference_Data!$AL$7,"Exemplary",IF(L15>=Reference_Data!$AL$8,"Commendable",IF(L15>=Reference_Data!$AL$9,"Meets Standard","Needs Improvement"))))) -> Needs Improvement | N15: =IF($A15="","",IF(OR(G15>0,K15>=Reference_Data!$AL$10),"Ineligible","Eligible")) -> Eligible | O15: =IF($A15="","",RANK(L15,$L$7:$L$106)) -> 9
A16: =IF(Employee_Master!A14="","",Employee_Master!A14) -> E-1010 | B16: =IF($A16="","",Employee_Master!B14) -> Jomar Dela Cruz | C16: =IF($A16="","",Employee_Master!C14) -> Design | D16: =IF($A16="","",COUNTIFS(Qualification_Log!$C$5:$C$304,$A16,Qualification_Log!$U$5:$U$304,"Active")) -> 1 | E16: =IF($A16="","",COUNTIFS(Qualification_Log!$C$5:$C$304,$A16,Qualification_Log!$Q$5:$Q$304,"Yes",Qualification_Log!$R$5:$R$304,">="&$B$3,Qualification_Log!$R$5:$R$304,"<="&$B$4)) -> 1 | F16: =IF($A16="","",COUNTIFS(Qualification_Log!$C$5:$C$304,$A16,Qualification_Log!$G$5:$G$304,"Quality Incident",Qualification_Log!$B$5:$B$304,">="&$B$3,Qualification_Log!$B$5:$B$304,"<="&$B$4)+COUNTIFS(Qualification_Log!$C$5:$C$304,$A16,Qualification_Log!$G$5:$G$304,"Decertification",Qualification_Log!$O$5:$O$304,"<>",Qualification_Log!$B$5:$B$304,">="&$B$3,Qualification_Log!$B$5:$B$304,"<="&$B$4)) -> 2 | G16: =IF($A16="","",COUNTIFS(Qualification_Log!$C$5:$C$304,$A16,Qualification_Log!$O$5:$O$304,"Critical",Qualification_Log!$B$5:$B$304,">="&$B$3,Qualification_Log!$B$5:$B$304,"<="&$B$4)) -> 1 | H16: =IF($A16="","",SUMIFS(Qualification_Log!$N$5:$N$304,Qualification_Log!$C$5:$C$304,$A16,Qualification_Log!$B$5:$B$304,">="&$B$3,Qualification_Log!$B$5:$B$304,"<="&$B$4)) -> 57000 | I16: =IF($A16="","",COUNTIFS(Recognition_Log!$C$5:$C$304,$A16,Recognition_Log!$N$5:$N$304,"Approved",Recognition_Log!$O$5:$O$304,">="&$B$3,Recognition_Log!$O$5:$O$304,"<="&$B$4)) -> 0 | J16: =IF($A16="","",SUMIFS(Recognition_Log!$Q$5:$Q$304,Recognition_Log!$C$5:$C$304,$A16,Recognition_Log!$O$5:$O$304,">="&$B$3,Recognition_Log!$O$5:$O$304,"<="&$B$4)) -> 0 | K16: =IF($A16="","",SUMIFS(Corrective_Action_Log!$T$5:$T$304,Corrective_Action_Log!$C$5:$C$304,$A16,Corrective_Action_Log!$N$5:$N$304,">="&$B$3,Corrective_Action_Log!$N$5:$N$304,"<="&$B$4)) -> 45 | L16: =IF($A16="","",J16-K16) -> -45 | M16: =IF($A16="","",IF(OR(G16>0,E16>0),"Under Review",IF(L16>=Reference_Data!$AL$7,"Exemplary",IF(L16>=Reference_Data!$AL$8,"Commendable",IF(L16>=Reference_Data!$AL$9,"Meets Standard","Needs Improvement"))))) -> Under Review | N16: =IF($A16="","",IF(OR(G16>0,K16>=Reference_Data!$AL$10),"Ineligible","Eligible")) -> Ineligible | O16: =IF($A16="","",RANK(L16,$L$7:$L$106)) -> 10
A17: =IF(Employee_Master!A15="","",Employee_Master!A15) | B17: =IF($A17="","",Employee_Master!B15) | C17: =IF($A17="","",Employee_Master!C15) | D17: =IF($A17="","",COUNTIFS(Qualification_Log!$C$5:$C$304,$A17,Qualification_Log!$U$5:$U$304,"Active")) | E17: =IF($A17="","",COUNTIFS(Qualification_Log!$C$5:$C$304,$A17,Qualification_Log!$Q$5:$Q$304,"Yes",Qualification_Log!$R$5:$R$304,">="&$B$3,Qualification_Log!$R$5:$R$304,"<="&$B$4)) | F17: =IF($A17="","",COUNTIFS(Qualification_Log!$C$5:$C$304,$A17,Qualification_Log!$G$5:$G$304,"Quality Incident",Qualification_Log!$B$5:$B$304,">="&$B$3,Qualification_Log!$B$5:$B$304,"<="&$B$4)+COUNTIFS(Qualification_Log!$C$5:$C$304,$A17,Qualification_Log!$G$5:$G$304,"Decertification",Qualification_Log!$O$5:$O$304,"<>",Qualification_Log!$B$5:$B$304,">="&$B$3,Qualification_Log!$B$5:$B$304,"<="&$B$4)) | G17: =IF($A17="","",COUNTIFS(Qualification_Log!$C$5:$C$304,$A17,Qualification_Log!$O$5:$O$304,"Critical",Qualification_Log!$B$5:$B$304,">="&$B$3,Qualification_Log!$B$5:$B$304,"<="&$B$4)) | H17: =IF($A17="","",SUMIFS(Qualification_Log!$N$5:$N$304,Qualification_Log!$C$5:$C$304,$A17,Qualification_Log!$B$5:$B$304,">="&$B$3,Qualification_Log!$B$5:$B$304,"<="&$B$4)) | I17: =IF($A17="","",COUNTIFS(Recognition_Log!$C$5:$C$304,$A17,Recognition_Log!$N$5:$N$304,"Approved",Recognition_Log!$O$5:$O$304,">="&$B$3,Recognition_Log!$O$5:$O$304,"<="&$B$4)) | J17: =IF($A17="","",SUMIFS(Recognition_Log!$Q$5:$Q$304,Recognition_Log!$C$5:$C$304,$A17,Recognition_Log!$O$5:$O$304,">="&$B$3,Recognition_Log!$O$5:$O$304,"<="&$B$4)) | K17: =IF($A17="","",SUMIFS(Corrective_Action_Log!$T$5:$T$304,Corrective_Action_Log!$C$5:$C$304,$A17,Corrective_Action_Log!$N$5:$N$304,">="&$B$3,Corrective_Action_Log!$N$5:$N$304,"<="&$B$4)) | L17: =IF($A17="","",J17-K17) | M17: =IF($A17="","",IF(OR(G17>0,E17>0),"Under Review",IF(L17>=Reference_Data!$AL$7,"Exemplary",IF(L17>=Reference_Data!$AL$8,"Commendable",IF(L17>=Reference_Data!$AL$9,"Meets Standard","Needs Improvement"))))) | N17: =IF($A17="","",IF(OR(G17>0,K17>=Reference_Data!$AL$10),"Ineligible","Eligible")) | O17: =IF($A17="","",RANK(L17,$L$7:$L$106))
A18: =IF(Employee_Master!A16="","",Employee_Master!A16) | B18: =IF($A18="","",Employee_Master!B16) | C18: =IF($A18="","",Employee_Master!C16) | D18: =IF($A18="","",COUNTIFS(Qualification_Log!$C$5:$C$304,$A18,Qualification_Log!$U$5:$U$304,"Active")) | E18: =IF($A18="","",COUNTIFS(Qualification_Log!$C$5:$C$304,$A18,Qualification_Log!$Q$5:$Q$304,"Yes",Qualification_Log!$R$5:$R$304,">="&$B$3,Qualification_Log!$R$5:$R$304,"<="&$B$4)) | F18: =IF($A18="","",COUNTIFS(Qualification_Log!$C$5:$C$304,$A18,Qualification_Log!$G$5:$G$304,"Quality Incident",Qualification_Log!$B$5:$B$304,">="&$B$3,Qualification_Log!$B$5:$B$304,"<="&$B$4)+COUNTIFS(Qualification_Log!$C$5:$C$304,$A18,Qualification_Log!$G$5:$G$304,"Decertification",Qualification_Log!$O$5:$O$304,"<>",Qualification_Log!$B$5:$B$304,">="&$B$3,Qualification_Log!$B$5:$B$304,"<="&$B$4)) | G18: =IF($A18="","",COUNTIFS(Qualification_Log!$C$5:$C$304,$A18,Qualification_Log!$O$5:$O$304,"Critical",Qualification_Log!$B$5:$B$304,">="&$B$3,Qualification_Log!$B$5:$B$304,"<="&$B$4)) | H18: =IF($A18="","",SUMIFS(Qualification_Log!$N$5:$N$304,Qualification_Log!$C$5:$C$304,$A18,Qualification_Log!$B$5:$B$304,">="&$B$3,Qualification_Log!$B$5:$B$304,"<="&$B$4)) | I18: =IF($A18="","",COUNTIFS(Recognition_Log!$C$5:$C$304,$A18,Recognition_Log!$N$5:$N$304,"Approved",Recognition_Log!$O$5:$O$304,">="&$B$3,Recognition_Log!$O$5:$O$304,"<="&$B$4)) | J18: =IF($A18="","",SUMIFS(Recognition_Log!$Q$5:$Q$304,Recognition_Log!$C$5:$C$304,$A18,Recognition_Log!$O$5:$O$304,">="&$B$3,Recognition_Log!$O$5:$O$304,"<="&$B$4)) | K18: =IF($A18="","",SUMIFS(Corrective_Action_Log!$T$5:$T$304,Corrective_Action_Log!$C$5:$C$304,$A18,Corrective_Action_Log!$N$5:$N$304,">="&$B$3,Corrective_Action_Log!$N$5:$N$304,"<="&$B$4)) | L18: =IF($A18="","",J18-K18) | M18: =IF($A18="","",IF(OR(G18>0,E18>0),"Under Review",IF(L18>=Reference_Data!$AL$7,"Exemplary",IF(L18>=Reference_Data!$AL$8,"Commendable",IF(L18>=Reference_Data!$AL$9,"Meets Standard","Needs Improvement"))))) | N18: =IF($A18="","",IF(OR(G18>0,K18>=Reference_Data!$AL$10),"Ineligible","Eligible")) | O18: =IF($A18="","",RANK(L18,$L$7:$L$106))
... A106: =IF(Employee_Master!A104="","",Employee_Master!A104) | B106: =IF($A106="","",Employee_Master!B104) | C106: =IF($A106="","",Employee_Master!C104) | D106: =IF($A106="","",COUNTIFS(Qualification_Log!$C$5:$C$304,$A106,Qualification_Log!$U$5:$U$304,"Active")) | E106: =IF($A106="","",COUNTIFS(Qualification_Log!$C$5:$C$304,$A106,Qualification_Log!$Q$5:$Q$304,"Yes",Qualification_Log!$R$5:$R$304,">="&$B$3,Qualification_Log!$R$5:$R$304,"<="&$B$4)) | F106: =IF($A106="","",COUNTIFS(Qualification_Log!$C$5:$C$304,$A106,Qualification_Log!$G$5:$G$304,"Quality Incident",Qualification_Log!$B$5:$B$304,">="&$B$3,Qualification_Log!$B$5:$B$304,"<="&$B$4)+COUNTIFS(Qualification_Log!$C$5:$C$304,$A106,Qualification_Log!$G$5:$G$304,"Decertification",Qualification_Log!$O$5:$O$304,"<>",Qualification_Log!$B$5:$B$304,">="&$B$3,Qualification_Log!$B$5:$B$304,"<="&$B$4)) | G106: =IF($A106="","",COUNTIFS(Qualification_Log!$C$5:$C$304,$A106,Qualification_Log!$O$5:$O$304,"Critical",Qualification_Log!$B$5:$B$304,">="&$B$3,Qualification_Log!$B$5:$B$304,"<="&$B$4)) | H106: =IF($A106="","",SUMIFS(Qualification_Log!$N$5:$N$304,Qualification_Log!$C$5:$C$304,$A106,Qualification_Log!$B$5:$B$304,">="&$B$3,Qualification_Log!$B$5:$B$304,"<="&$B$4)) | I106: =IF($A106="","",COUNTIFS(Recognition_Log!$C$5:$C$304,$A106,Recognition_Log!$N$5:$N$304,"Approved",Recognition_Log!$O$5:$O$304,">="&$B$3,Recognition_Log!$O$5:$O$304,"<="&$B$4)) | J106: =IF($A106="","",SUMIFS(Recognition_Log!$Q$5:$Q$304,Recognition_Log!$C$5:$C$304,$A106,Recognition_Log!$O$5:$O$304,">="&$B$3,Recognition_Log!$O$5:$O$304,"<="&$B$4)) | K106: =IF($A106="","",SUMIFS(Corrective_Action_Log!$T$5:$T$304,Corrective_Action_Log!$C$5:$C$304,$A106,Corrective_Action_Log!$N$5:$N$304,">="&$B$3,Corrective_Action_Log!$N$5:$N$304,"<="&$B$4)) | L106: =IF($A106="","",J106-K106) | M106: =IF($A106="","",IF(OR(G106>0,E106>0),"Under Review",IF(L106>=Reference_Data!$AL$7,"Exemplary",IF(L106>=Reference_Data!$AL$8,"Commendable",IF(L106>=Reference_Data!$AL$9,"Meets Standard","Needs Improvement"))))) | N106: =IF($A106="","",IF(OR(G106>0,K106>=Reference_Data!$AL$10),"Ineligible","Eligible")) | O106: =IF($A106="","",RANK(L106,$L$7:$L$106))

Sheet Qualification_Log
A1: Process Qualification & Performance Log
A2: Log every certification, assessment, quality incident (with Cost of Quality), and decertification. One event per row.
A3: Legend: Navy header = input (enter / select from dropdown) | Grey header + shaded cells = auto-calculated (do not overwrite)
